Workbook
Name \a: #REF!
Name \e: #REF!
Name _25KgNAL: #REF!
Name _42.5KgEXP: #REF!
Name _42.5KgNAL: #REF!
Name _42.5KgRIO: #REF!
Name _50_KgNAL: #REF!
Name _50KgV300: #REF!
Name _AtRisk_SimSetting_AutomaticallyGenerateReports: FALSE
Name _AtRisk_SimSetting_AutomaticResultsDisplayMode: 0
Name _AtRisk_SimSetting_ConvergenceConfidenceLevel: 0.95
Name _AtRisk_SimSetting_ConvergencePercentileToTest: 0.9
Name _AtRisk_SimSetting_ConvergencePerformMeanTest: TRUE
Name _AtRisk_SimSetting_ConvergencePerformPercentileTest: FALSE
Name _AtRisk_SimSetting_ConvergencePerformStdDeviationTest: FALSE
Name _AtRisk_SimSetting_ConvergenceTestAllOutputs: TRUE
Name _AtRisk_SimSetting_ConvergenceTestingPeriod: 100
Name _AtRisk_SimSetting_ConvergenceTolerance: 0.03
Name _AtRisk_SimSetting_LiveUpdate: TRUE
Name _AtRisk_SimSetting_LiveUpdatePeriod: -1
Name _AtRisk_SimSetting_RandomNumberGenerator: 0
Name _AtRisk_SimSetting_ReportsList: 1
Name _AtRisk_SimSetting_SimNameCount: 0
Name _AtRisk_SimSetting_SmartSensitivityAnalysisEnabled: TRUE
Name _AtRisk_SimSetting_StatisticFunctionUpdating: 1
Name _AtRisk_SimSetting_StdRecalcBehavior: 0
Name _AtRisk_SimSetting_StdRecalcWithoutRiskStatic: 0
Name _AtRisk_SimSetting_StdRecalcWithoutRiskStaticPercentile: 0.5
Name _AV20025: #REF!
Name _AV200251: #REF!
Name _AV20050: #REF!
Name _AV200501: #REF!
Name _CAL96: #REF!
Name _CEM96: #REF!
Name _EMP96: #REF!
Name _ESC96: #REF!
Name _GAS1: #REF!
Name _INF1: #REF!
Name _MES1997: #REF!
Name _MO96: #REF!
Name _MOE1: #REF!
Name _MOF1: #REF!
Name _MOL3: #REF!
Name _MOL4: #REF!
Name _MOL5: #REF!
Name _MOL6: #REF!
Name _MOL7: #REF!
Name _MP96: #REF!
Name _NAL25: #REF!
Name _Regression_Int: 1
Name A_impresión_IM: #REF!
Name A1_CVC: #REF!
Name A2_CVC: #REF!
Name A25NAL: #REF!
Name A42.5EXP: #REF!
Name A42.5KgRIO: #REF!
Name A42.5NAL: #REF!
Name A50KgV300: #REF!
Name A50NAL: #REF!
Name AACPM: #REF!

Sheet Datos
B1: Tipo | C1: UM | D1: 45901 | E1: 45931 | F1: 45962 | G1: 45992 | H1: 46023 | I1: 46054 | J1: 46082 | K1: 46113 | L1: 46143 | M1: 46174 | N1: 46204 | O1: 46235 | P1: 46266 | Q1: 46296 | R1: 46327 | S1: 46357
B2: Precios
B3: Caliza + Martillo | C3: COP/Ton | D3: =D4*0.9+(D4+D6)*0.1 -> 14277.344 | E3: =E4*0.9+(E4+E6)*0.1 -> 14277.344 | F3: =F4*0.9+(F4+F6)*0.1 -> 14277.344 | G3: =G4*0.9+(G4+G6)*0.1 -> 14277.344 | H3: =H4*H129+(H4+H6)*H130 -> 13978.132 | I3: =I4*I129+(I4+I6)*I130 -> 13978.132 | J3: =J4*J129+(J4+J6)*J130 -> 13978.132 | K3: =K4*K129+(K4+K6)*K130 -> 13978.132 | L3: =L4*L129+(L4+L6)*L130 -> 13978.132 | M3: =M4*M129+(M4+M6)*M130 -> 13978.132 | N3: =N4*N129+(N4+N6)*N130 -> 13978.132 | O3: =O4*O129+(O4+O6)*O130 -> 13978.132 | ... S3: =S4*S129+(S4+S6)*S130 -> 13978.132
B4: Caliza Explotada | C4: COP/Ton | D4: 13974.06 | E4: 13974.06 | F4: 13974.06 | G4: 13974.06 | H4: 13819.211 | I4: =H4 -> 13819.211 | J4: =I4 -> 13819.211 | K4: =J4 -> 13819.211 | L4: =K4 -> 13819.211 | M4: =L4 -> 13819.211 | N4: =M4 -> 13819.211 | O4: =N4 -> 13819.211 | P4: =O4 -> 13819.211 | ... S4: =R4 -> 13819.211
B5: Arcilla Explotada | C5: COP/Ton | D5: 11628.05 | E5: 11628.05 | F5: 11628.05 | G5: 11628.05 | H5: 10623.146 | I5: 10623.146 | J5: 10623.146 | K5: 10623.146 | L5: 10623.146 | M5: 10623.146 | N5: 10623.146 | O5: 10623.146 | P5: 10623.146 | Q5: 10623.146 | R5: 10623.146 | S5: 10623.146
B6: Costo Adicional Martillo | C6: COP/Ton | D6: 3032.84 | E6: 3032.84 | F6: 3032.84 | G6: 3032.84 | H6: 3178.4163 | I6: 3178.4163 | J6: 3178.4163 | K6: 3178.4163 | L6: 3178.4163 | M6: 3178.4163 | N6: 3178.4163 | O6: 3178.4163 | P6: 3178.4163 | Q6: 3178.4163 | R6: 3178.4163 | S6: 3178.4163
B7: Caliza Comprada a Externos | C7: COP/Ton | D7: 36831.382 | E7: 36831.382 | F7: 36831.382 | G7: 36831.382 | H7: 36831.382 | I7: 36831.382 | J7: 36831.382 | K7: 36831.382 | L7: 36831.382 | M7: 36831.382 | N7: 36831.382 | O7: 36831.382 | P7: 36831.382 | Q7: 36831.382 | R7: 36831.382 | S7: 36831.382
B8: Carbón Fino | C8: COP/Ton | D8: =D16*0.5+D17*0.5 -> 174584.14 | E8: =E16*0.5+E17*0.5 -> 174584.14 | F8: =F16*0.5+F17*0.5 -> 174584.14 | G8: =G16*0.5+G17*0.5 -> 174584.14 | H8: =H16*H136+H17*H137 -> 209813.2 | I8: =I16*I136+I17*I137 -> 209813.2 | J8: =J16*J136+J17*J137 -> 209813.2 | K8: =K16*K136+K17*K137 -> 209813.2 | L8: =L16*L136+L17*L137 -> 209813.2 | M8: =M16*M136+M17*M137 -> 209813.2 | N8: =N16*N136+N17*N137 -> 209813.2 | O8: =O16*O136+O17*O137 -> 209813.2 | ... S8: =S16*S136+S17*S137 -> 209813.2
B9: Carbón Mixto | C9: COP/Ton | D9: =D18*0.43+D19*0.36+D20*0.21 -> 142315.38 | E9: =E18*0.43+E19*0.36+E20*0.21 -> 142315.38 | F9: =F18*0.43+F19*0.36+F20*0.21 -> 142315.38 | G9: =G18*0.43+G19*0.36+G20*0.21 -> 142315.38 | H9: =H18*H138+H19*H139+H20*H140 -> 149376.25 | I9: =I18*I138+I19*I139+I20*I140 -> 149376.25 | J9: =J18*J138+J19*J139+J20*J140 -> 149376.25 | K9: =K18*K138+K19*K139+K20*K140 -> 149376.25 | L9: =L18*L138+L19*L139+L20*L140 -> 149376.25 | M9: =M18*M138+M19*M139+M20*M140 -> 149376.25 | N9: =N18*N138+N19*N139+N20*N140 -> 149376.25 | O9: =O18*O138+O19*O139+O20*O140 -> 149376.25 | ... S9: =S18*S138+S19*S139+S20*S140 -> 149376.25
B10: Carbón Bituminoso | C10: COP/Ton | D10: =D11*0.3+D12*0.3+D13*0.05+D14*0.17+D15*0.18 -> 337846.06 | E10: =E11*0.3+E12*0.3+E13*0.05+E14*0.17+E15*0.18 -> 337846.06 | F10: =F11*0.3+F12*0.3+F13*0.05+F14*0.17+F15*0.18 -> 337846.06 | G10: =G11*0.3+G12*0.3+G13*0.05+G14*0.17+G15*0.18 -> 337846.06 | H10: =H11*H131+H12*H132+H13*H133+H14*H134+H15*H135 -> 345241.54 | I10: =I11*I131+I12*I132+I13*I133+I14*I134+I15*I135 -> 345241.54 | J10: =J11*J131+J12*J132+J13*J133+J14*J134+J15*J135 -> 345241.54 | K10: =K11*K131+K12*K132+K13*K133+K14*K134+K15*K135 -> 345241.54 | L10: =L11*L131+L12*L132+L13*L133+L14*L134+L15*L135 -> 345241.54 | M10: =M11*M131+M12*M132+M13*M133+M14*M134+M15*M135 -> 345241.54 | N10: =N11*N131+N12*N132+N13*N133+N14*N134+N15*N135 -> 345241.54 | O10: =O11*O131+O12*O132+O13*O133+O14*O134+O15*O135 -> 345241.54 | ... S10: =S11*S131+S12*S132+S13*S133+S14*S134+S15*S135 -> 345241.54
B11: Sanoha | C11: COP/Ton | D11: 364231.24 | E11: 364231.24 | F11: 364231.24 | G11: 364231.24 | H11: 367329.3 | I11: 367329.3 | J11: 367329.3 | K11: 367329.3 | L11: 367329.3 | M11: 367329.3 | N11: 367329.3 | O11: 367329.3 | P11: 367329.3 | Q11: 367329.3 | R11: 367329.3 | S11: 367329.3
B12: Forero Hernandez | C12: COP/Ton | D12: 363394 | E12: 363394 | F12: 363394 | G12: 363394 | H12: 379673.75 | I12: 379673.75 | J12: 379673.75 | K12: 379673.75 | L12: 379673.75 | M12: 379673.75 | N12: 379673.75 | O12: 379673.75 | P12: 379673.75 | Q12: 379673.75 | R12: 379673.75 | S12: 379673.75
B13: Tottal Carbón | C13: COP/Ton | D13: 336354.44 | E13: 336354.44 | F13: 336354.44 | G13: 336354.44 | H13: 332646.3 | I13: 332646.3 | J13: 332646.3 | K13: 332646.3 | L13: 332646.3 | M13: 332646.3 | N13: 332646.3 | O13: 332646.3 | P13: 332646.3 | Q13: 332646.3 | R13: 332646.3 | S13: 332646.3
B14: Soluciones De Carbón Colombia | C14: COP/Ton | D14: 336354.44 | E14: 336354.44 | F14: 336354.44 | G14: 336354.44 | H14: 332646.3 | I14: 332646.3 | J14: 332646.3 | K14: 332646.3 | L14: 332646.3 | M14: 332646.3 | N14: 332646.3 | O14: 332646.3 | P14: 332646.3 | Q14: 332646.3 | R14: 332646.3 | S14: 332646.3
B15: Minas Las Margaritas | C15: COP/Ton | D15: 253113.97 | E15: 253113.97 | F15: 253113.97 | G15: 253113.97 | H15: 266435.76 | I15: 266435.76 | J15: 266435.76 | K15: 266435.76 | L15: 266435.76 | M15: 266435.76 | N15: 266435.76 | O15: 266435.76 | P15: 266435.76 | Q15: 266435.76 | R15: 266435.76 | S15: 266435.76
B16: C I Interamerican Conmina (Fortia Minerals) | C16: COP/Ton | D16: 174584.14 | E16: 174584.14 | F16: 174584.14 | G16: 174584.14 | H16: 209813.2 | I16: 209813.2 | J16: 209813.2 | K16: 209813.2 | L16: 209813.2 | M16: 209813.2 | N16: 209813.2 | O16: 209813.2 | P16: 209813.2 | Q16: 209813.2 | R16: 209813.2 | S16: 209813.2
B17: Trancora Sas | C17: COP/Ton | D17: 174584.14 | E17: 174584.14 | F17: 174584.14 | G17: 174584.14 | H17: 209813.2 | I17: 209813.2 | J17: 209813.2 | K17: 209813.2 | L17: 209813.2 | M17: 209813.2 | N17: 209813.2 | O17: 209813.2 | P17: 209813.2 | Q17: 209813.2 | R17: 209813.2 | S17: 209813.2
B18: Mixto Carbones Andino | C18: COP/Ton | D18: 141616.48 | E18: 141616.48 | F18: 141616.48 | G18: 141616.48 | H18: 148649.3 | I18: 148649.3 | J18: 148649.3 | K18: 148649.3 | L18: 148649.3 | M18: 148649.3 | N18: 148649.3 | O18: 148649.3 | P18: 148649.3 | Q18: 148649.3 | R18: 148649.3 | S18: 148649.3
B19: Mixtos Carbocoque | C19: COP/Ton | D19: 134584.14 | E19: 134584.14 | F19: 134584.14 | G19: 134584.14 | H19: 141253.2 | I19: 141253.2 | J19: 141253.2 | K19: 141253.2 | L19: 141253.2 | M19: 141253.2 | N19: 141253.2 | O19: 141253.2 | P19: 141253.2 | Q19: 141253.2 | R19: 141253.2 | S19: 141253.2
B20: Mixto Coquecol | C20: COP/Ton | D20: 157000 | E20: 157000 | F20: 157000 | G20: 157000 | H20: 164790 | I20: 164790 | J20: 164790 | K20: 164790 | L20: 164790 | M20: 164790 | N20: 164790 | O20: 164790 | P20: 164790 | Q20: 164790 | R20: 164790 | S20: 164790
B21: Flete (Boyacá - Planta)-Socha | C21: COP/Ton | D21: 108388 | E21: 112723.52 | F21: 112723.52 | G21: 112723.52 | H21: 133350 | I21: 133350 | J21: 133350 | K21: 133350 | L21: 133350 | M21: 133350 | N21: 133350 | O21: 133350 | P21: 133350 | Q21: 133350 | R21: 133350 | S21: 133350
B22: Flete (Boyacá - Planta) | C22: COP/Ton | D22: 96379 | E22: 100234.16 | F22: 100234.16 | G22: 100234.16 | H22: 123497.3 | I22: 123497.3 | J22: 123497.3 | K22: 123497.3 | L22: 123497.3 | M22: 123497.3 | N22: 123497.3 | O22: 123497.3 | P22: 123497.3 | Q22: 123497.3 | R22: 123497.3 | S22: 123497.3
... B25: Flete (Caldas - Planta) | C25: COP/Ton | D25: 60000 | E25: 62400 | F25: 62400 | G25: 62400 | H25: 68363.757 | I25: 68363.757 | J25: 68363.757 | K25: 68363.757 | L25: 68363.757 | M25: 68363.757 | N25: 68363.757 | O25: 68363.757 | P25: 68363.757 | Q25: 68363.757 | R25: 68363.757 | S25: 68363.757
B26: Cdr | C26: COP/Ton | D26: =D30*0.5+D31*0.05+D32*0.12+D33*0.15+D34*0.02+D35*0.01+D36*0.15+D37*0 -> 310957.52 | E26: =E30*0.5+E31*0.05+E32*0.12+E33*0.15+E34*0.02+E35*0.01+E36*0.15+E37*0 -> 310957.52 | F26: =F30*0.5+F31*0.05+F32*0.12+F33*0.15+F34*0.02+F35*0.01+F36*0.15+F37*0 -> 310957.52 | G26: =G30*0.5+G31*0.05+G32*0.12+G33*0.15+G34*0.02+G35*0.01+G36*0.15+G37*0 -> 310957.52 | H26: =H30*H141+H31*H142+H32*H143+H33*H144+H34*H145+H35*H146+H36*H147+H37*H148 -> 318229.74 | I26: =I30*0.5+I31*0.05+I32*0.12+I33*0.15+I34*0.02+I35*0.01+I36*0.15+I37*0 -> 318229.74 | J26: =J30*0.5+J31*0.05+J32*0.12+J33*0.15+J34*0.02+J35*0.01+J36*0.15+J37*0 -> 318229.74 | K26: =K30*0.5+K31*0.05+K32*0.12+K33*0.15+K34*0.02+K35*0.01+K36*0.15+K37*0 -> 318229.74 | L26: =L30*0.5+L31*0.05+L32*0.12+L33*0.15+L34*0.02+L35*0.01+L36*0.15+L37*0 -> 318229.74 | M26: =M30*0.5+M31*0.05+M32*0.12+M33*0.15+M34*0.02+M35*0.01+M36*0.15+M37*0 -> 318229.74 | N26: =N30*0.5+N31*0.05+N32*0.12+N33*0.15+N34*0.02+N35*0.01+N36*0.15+N37*0 -> 318229.74 | O26: =O30*0.5+O31*0.05+O32*0.12+O33*0.15+O34*0.02+O35*0.01+O36*0.15+O37*0 -> 318229.74 | P26: =P30*0.5+P31*0.05+P32*0.12+P33*0.15+P34*0.02+P35*0.01+P36*0.15+P37*0 -> 318229.74 | ... S26: =S30*0.5+S31*0.05+S32*0.12+S33*0.15+S34*0.02+S35*0.01+S36*0.15+S37*0 -> 318229.74
B27: Tdf | C27: COP/Ton | D27: =D38*0.3+D39*0.3+D40*0.4 -> 304467.55 | E27: =E38*0.3+E39*0.3+E40*0.4 -> 304467.55 | F27: =F38*0.3+F39*0.3+F40*0.4 -> 304467.55 | G27: =G38*0.3+G39*0.3+G40*0.4 -> 304467.55 | H27: =H38*H149+H39*H150+H40*H151 -> 318422.6 | I27: =I38*I149+I39*I150+I40*I151 -> 318422.6 | J27: =J38*J149+J39*J150+J40*J151 -> 318422.6 | K27: =K38*K149+K39*K150+K40*K151 -> 318422.6 | L27: =L38*L149+L39*L150+L40*L151 -> 318422.6 | M27: =M38*M149+M39*M150+M40*M151 -> 318422.6 | N27: =N38*N149+N39*N150+N40*N151 -> 318422.6 | O27: =O38*O149+O39*O150+O40*O151 -> 318422.6 | ... S27: =S38*S149+S39*S150+S40*S151 -> 318422.6
B28: Briquetas | C28: COP/Ton | D28: =+D41 -> 322952.38 | E28: =+E41 -> 322952.38 | F28: =+F41 -> 322952.38 | G28: =+G41 -> 322952.38 | H28: =+H41 -> 335465.18 | I28: =+I41 -> 335465.18 | J28: =+J41 -> 335465.18 | K28: =+K41 -> 335465.18 | ... S28: =+S41 -> 335465.18
B29: Chips | C29: COP/Ton | D29: =+D42 -> 283952.38 | E29: =+E42 -> 283952.38 | F29: =+F42 -> 283952.38 | G29: =+G42 -> 283952.38 | H29: =+H42 -> 294593.18 | I29: =+I42 -> 294593.18 | J29: =+J42 -> 294593.18 | K29: =+K42 -> 294593.18 | ... S29: =+S42 -> 294593.18
B30: Cdr Focus Green Antioquia | C30: COP/Ton | D30: 318052.38 | E30: 318052.38 | F30: 318052.38 | G30: 318052.38 | H30: 330329.98 | I30: 330329.98 | J30: 330329.98 | K30: 330329.98 | L30: 330329.98 | M30: 330329.98 | N30: 330329.98 | O30: 330329.98 | P30: 330329.98 | Q30: 330329.98 | R30: 330329.98 | S30: 330329.98
B31: Cdr Sistema Verde Cundinamarca | C31: COP/Ton | D31: 289488.34 | E31: 289488.34 | F31: 289488.34 | G31: 289488.34 | H31: 303722.76 | I31: 303722.76 | J31: 303722.76 | K31: 303722.76 | L31: 303722.76 | M31: 303722.76 | N31: 303722.76 | O31: 303722.76 | P31: 303722.76 | Q31: 303722.76 | R31: 303722.76 | S31: 303722.76
B32: Cdr Sistema Verde Antioquia | C32: COP/Ton | D32: 253952.38 | E32: 253952.38 | F32: 253952.38 | G32: 253952.38 | H32: 263153.18 | I32: 263153.18 | J32: 263153.18 | K32: 263153.18 | L32: 263153.18 | M32: 263153.18 | N32: 263153.18 | O32: 263153.18 | P32: 263153.18 | Q32: 263153.18 | R32: 263153.18 | S32: 263153.18
B33: Cdr Ecologística | C33: COP/Ton | D33: 343952.38 | E33: 343952.38 | F33: 343952.38 | G33: 343952.38 | H33: 357473.18 | I33: 357473.18 | J33: 357473.18 | K33: 357473.18 | L33: 357473.18 | M33: 357473.18 | N33: 357473.18 | O33: 357473.18 | P33: 357473.18 | Q33: 357473.18 | R33: 357473.18 | S33: 357473.18
B34: Cdr Ecopositiva | C34: COP/Ton | D34: 269488.34 | E34: 269488.34 | F34: 269488.34 | G34: 269488.34 | H34: 282762.76 | I34: 282762.76 | J34: 282762.76 | K34: 282762.76 | L34: 282762.76 | M34: 282762.76 | N34: 282762.76 | O34: 282762.76 | P34: 282762.76 | Q34: 282762.76 | R34: 282762.76 | S34: 282762.76
B35: Cdr Veolia | C35: COP/Ton | D35: 312500 | E35: 312500 | F35: 312500 | G35: 312500 | H35: 293900 | I35: 293900 | J35: 293900 | K35: 293900 | L35: 293900 | M35: 293900 | N35: 293900 | O35: 293900 | P35: 293900 | Q35: 293900 | R35: 293900 | S35: 293900
B36: Cdr Gdi-Cali | C36: COP/Ton | D36: 312500 | E36: 312500 | F36: 312500 | G36: 312500 | H36: 293900 | I36: 293900 | J36: 293900 | K36: 293900 | L36: 293900 | M36: 293900 | N36: 293900 | O36: 293900 | P36: 293900 | Q36: 293900 | R36: 293900 | S36: 293900
B37: Cdr Gdi-Zipaquirá | C37: COP/Ton | D37: 226388.34 | E37: 226388.34 | F37: 226388.34 | G37: 226388.34 | H37: 237593.96 | I37: 237593.96 | J37: 237593.96 | K37: 237593.96 | L37: 237593.96 | M37: 237593.96 | N37: 237593.96 | O37: 237593.96 | P37: 237593.96 | Q37: 237593.96 | R37: 237593.96 | S37: 237593.96
B38: Tdf Sistema Verde Cundinamarca | C38: COP/Ton | D38: 289488.34 | E38: 289488.34 | F38: 289488.34 | G38: 289488.34 | H38: 303722.76 | I38: 303722.76 | J38: 303722.76 | K38: 303722.76 | L38: 303722.76 | M38: 303722.76 | N38: 303722.76 | O38: 303722.76 | P38: 303722.76 | Q38: 303722.76 | R38: 303722.76 | S38: 303722.76
B39: Tdf Sistema Verde Antioquia | C39: COP/Ton | D39: 253952.38 | E39: 253952.38 | F39: 253952.38 | G39: 253952.38 | H39: 263153.18 | I39: 263153.18 | J39: 263153.18 | K39: 263153.18 | L39: 263153.18 | M39: 263153.18 | N39: 263153.18 | O39: 263153.18 | P39: 263153.18 | Q39: 263153.18 | R39: 263153.18 | S39: 263153.18
B40: Tdf Focus Green Cundinamarca | C40: COP/Ton | D40: 353588.34 | E40: 353588.34 | F40: 353588.34 | G40: 353588.34 | H40: 370899.56 | I40: 370899.56 | J40: 370899.56 | K40: 370899.56 | L40: 370899.56 | M40: 370899.56 | N40: 370899.56 | O40: 370899.56 | P40: 370899.56 | Q40: 370899.56 | R40: 370899.56 | S40: 370899.56
B41: Briquetas Arclad | C41: COP/Ton | D41: 322952.38 | E41: 322952.38 | F41: 322952.38 | G41: 322952.38 | H41: 335465.18 | I41: 335465.18 | J41: 335465.18 | K41: 335465.18 | L41: 335465.18 | M41: 335465.18 | N41: 335465.18 | O41: 335465.18 | P41: 335465.18 | Q41: 335465.18 | R41: 335465.18 | S41: 335465.18
... B44: Tdf Focus Green Cundinamarca | C44: COP/Ton | D44: 211556.46 | E44: 211556.46 | F44: 211556.46 | G44: 211556.46 | H44: 213675 | I44: 213675 | J44: 213675 | K44: 213675 | L44: 213675 | M44: 213675 | N44: 213675 | O44: 213675 | P44: 213675 | Q44: 213675 | R44: 213675 | S44: 213675
...

Sheet ORD
A1: Material | B1: Proceso | C1: ORD
A2: MEZCLA PREHOMO | B2: Trituración | C2: 1
A3: CALIZA PARA ADICIONES | B3: Adiciones | C3: 2
A4: HARINA CRUDA | B4: Molienda de Crudo | C4: 3
A5: CARBON MOLIDO | B5: Molienda de Carbón | C5: 4
A6: CLINKER | B6: Clinkerización | C6: 5
A7: CEMENTO UG | B7: Cemento UG | C7: 6
A8: CEMENTO ART | B8: Cemento ART | C8: 7
A9: CEMENTO UG 50 KG | B9: CEMENTO UG 50 KG | C9: 8
A10: CEMENTO UG 42,5 KG | B10: CEMENTO UG 42,5 KG | C10: 9
A11: CEMENTO UG 25 KG | B11: CEMENTO UG 25 KG | C11: 10
A12: CEMENTO ART 42,5 KG | B12: CEMENTO ART 42,5 KG | C12: 11
A13: CEMENTO TOPEX 50 KG | B13: CEMENTO TOPEX 50 KG | C13: 14
... A18: CEMENTOS | B18: Cementos | C18: 21

Sheet Maestro
A1: Concatenado | B1: Clase de coste | C1: Denom.clase de coste | D1: Material | E1: Mat2 | F1: Proceso | G1: ORD | H1: Tp | J1: Orden | K1: Clasif
A2: =B2&D2&F2 -> 7199990001CALTLVTRITTrituración | B2: 7199990001 | C2: CONSUMOS SEMIELBORAD | D2: CALTLVTRIT | E2: MEZCLA PREHOMO | F2: Trituración | G2: 1 | H2: Caliza | J2: 700000 | K2: HARINA CRUDA
A3: =B3&D3&F3 -> 7199990001ARCTLVTRITTrituración | B3: 7199990001 | C3: CONSUMOS SEMIELBORAD | D3: ARCTLVTRIT | E3: MEZCLA PREHOMO | F3: Trituración | G3: 1 | H3: Arcilla | J3: 700001 | K3: CLINKER
A4: =B4&D4&F4 -> 7105330101CALIZATRIMolienda de Crudo | B4: 7105330101 | C4: CTO. MP CALIZAS NAL | D4: CALIZATRI | E4: HARINA CRUDA | F4: Molienda de Crudo | G4: 3 | H4: Caliza | J4: 700002 | K4: CARBON MOLIDO
A5: =B5&D5&F5 -> 7105330101MEZCPREHOMolienda de Crudo | B5: 7105330101 | C5: CTO. MP CALIZAS NAL | D5: MEZCPREHO | E5: HARINA CRUDA | F5: Molienda de Crudo | G5: 3 | H5: Prehomo | J5: 700003 | K5: CEMENTO UG
A6: =B6&D6&F6 -> 7105040101CORRHIERRMolienda de Crudo | B6: 7105040101 | C6: MP CORRECT HIERO NAL | D6: CORRHIERR | E6: HARINA CRUDA | F6: Molienda de Crudo | G6: 3 | H6: Mineral de Hierro | J6: 700004 | K6: CEMENTO UG 42,5 KG
A7: =B7&D7&F7 -> 7355050103CARBITUMIMolienda de Carbón | B7: 7355050103 | C7: CTO COMBUS SOL NAC | D7: CARBITUMI | E7: CARBON MOLIDO | F7: Molienda de Carbón | G7: 4 | H7: Carbón | J7: 700005 | K7: CALIZA PARA ADICIONES
A8: =B8&D8&F8 -> 7199990001CARBONMOLClinkerización | B8: 7199990001 | C8: CONSUMOS SEMIELBORAD | D8: CARBONMOL | E8: CLINKER | F8: Clinkerización | G8: 5 | H8: Carbón Molido | J8: 700006 | K8: CALIZA EN TOLVA TRITURADORA
A9: =B9&D9&F9 -> 7199990001HARINACRUDClinkerización | B9: 7199990001 | C9: CONSUMOS SEMIELBORAD | D9: HARINACRUD | E9: CLINKER | F9: Clinkerización | G9: 5 | H9: Crudo | J9: 700007 | K9: MEZCLA PREHOMO
A10: =B10&D10&F10 -> 735505010470000000034Clinkerización | B10: 7355050104 | C10: CTO COMBUS GAS NAC | D10: 70000000034 | E10: CLINKER | F10: Clinkerización | G10: 5 | H10: Gasoil | J10: 700008 | K10: ARCILLA EN TOLVA TRITURADORA
A11: =B11&D11&F11 -> 735505010570000000000Clinkerización | B11: 7355050105 | C11: CTO COMBUS LIQ NAC | D11: 70000000000 | E11: CLINKER | F11: Clinkerización | G11: 5 | H11: Gasoil | J11: 700070 | K11: COMBUSTIBLES ALTERNOS
A12: =B12&D12&F12 -> 7199990001CLINKER001Cemento UG | B12: 7199990001 | C12: CONSUMOS SEMIELBORAD | D12: CLINKER001 | E12: CEMENTO UG | F12: Cemento UG | G12: 6 | H12: Clinker | J12: 700034 | K12: CEMENTO ART 42,5 KG
A13: =B13&D13&F13 -> 7105450101YESO00001Cemento UG | B13: 7105450101 | C13: CTO. MP YES/ESCA NAL | D13: YESO00001 | E13: CEMENTO UG | F13: Cemento UG | G13: 6 | H13: Yeso | J13: 700037 | K13: CEMENTO ART 50 KG
A14: =B14&D14&F14 -> 7105330101CALIZATRICemento UG | B14: 7105330101 | C14: CTO. MP CALIZAS NAL | D14: CALIZATRI | E14: CEMENTO UG | F14: Cemento UG | G14: 6 | H14: Caliza Triturada | J14: 700040 | K14: CEMENTO A GRANEL ART
A15: =B15&D15&F15 -> 7199990001CLINKER001Cemento ART | B15: 7199990001 | C15: CONSUMOS SEMIELBORAD | D15: CLINKER001 | E15: CEMENTO ART | F15: Cemento ART | G15: 7 | H15: Clinker | J15: 700053 | K15: CEMENTO UG 50 KG
A16: =B16&D16&F16 -> 7105450101YESO00001Cemento ART | B16: 7105450101 | C16: CTO. MP YES/ESCA NAL | D16: YESO00001 | E16: CEMENTO ART | F16: Cemento ART | G16: 7 | H16: Yeso | J16: 700055 | K16: CEMENTO UG 50 KG
A17: =B17&D17&F17 -> 7105330101CALIZATRICemento ART | B17: 7105330101 | C17: CTO. MP CALIZAS NAL | D17: CALIZATRI | E17: CEMENTO ART | F17: Cemento ART | G17: 7 | H17: Caliza Triturada | J17: 700060 | K17: CEMENTO ART
A18: =B18&D18&F18 -> 7199990001CALTLVTRITAdiciones | B18: 7199990001 | C18: CONSUMOS SEMIELBORAD | D18: CALTLVTRIT | E18: CALIZA PARA ADICIONES | F18: Adiciones | G18: 2 | H18: Caliza | J18: 700048 | K18: CEMENTO UG 25 KG
A19: =B19&D19&F19 -> 735505010570000000000Cemento UG | B19: 7355050105 | C19: CTO COMBUS LIQ NAC | D19: 70000000000 | E19: CLINKER | F19: Cemento UG | G19: 6 | H19: Gasoil | J19: 700080 | K19: CEMENTO TOPEX 50 KG
A20: =B20&D20&F20 -> 7199990001CEMENTOARTCEMENTO ART 42,5 KG | B20: 7199990001 | C20: CONSUMOS SEMIELBORAD | D20: CEMENTOART | E20: CEMENTO ART 42,5 KG | F20: CEMENTO ART 42,5 KG | G20: 11 | H20: Cemento ART | J20: 700083 | K20: CALIZA PARA ADICIONES
A21: =B21&D21&F21 -> 736005030222000000005CEMENTO ART 42,5 KG | B21: 7360050302 | C21: CTO BOLSAS IMP | D21: 22000000005 | E21: CEMENTO ART 42,5 KG | F21: CEMENTO ART 42,5 KG | G21: 11 | H21: Sacos | J21: 700036 | K21: CEMENTO ART 42,5 KG
A22: =B22&D22&F22 -> 7199990001CEMENTOUG1CEMENTO UG 50 KG | B22: 7199990001 | C22: CONSUMOS SEMIELBORAD | D22: CEMENTOUG1 | E22: CEMENTO UG 50 KG | F22: CEMENTO UG 50 KG | G22: 8 | H22: Cemento UG | J22: 700050 | K22: CEMENTO UG 25 KG
A23: =B23&D23&F23 -> 736005030222000000008CEMENTO UG 50 KG | B23: 7360050302 | C23: CTO BOLSAS IMP | D23: 22000000008 | E23: CEMENTO UG 50 KG | F23: CEMENTO UG 50 KG | G23: 8 | H23: Sacos | J23: 700052 | K23: CEMENTO UG 42,5 KG
A24: =B24&D24&F24 -> 7199990001CEMENTO ARTCEMENTO A GRANEL ART | B24: 7199990001 | C24: CONSUMOS SEMIELBORAD | D24: CEMENTO ART | E24: CEMENTO A GRANEL ART | F24: CEMENTO A GRANEL ART | G24: 12 | H24: Cemento ART | J24: 700090 | K24: CEMENTO UG TP
A25: =B25&D25&F25 -> 7199990001CEMENTO ARTCEMENTO ART 50 KG | B25: 7199990001 | C25: CONSUMOS SEMIELBORAD | D25: CEMENTO ART | E25: CEMENTO ART 50 KG | F25: CEMENTO ART 50 KG | G25: 13 | H25: Cemento ART | J25: 700091 | K25: FIBROCEMENTO
A26: =B26&D26&F26 -> 7199990001CEMENTOUG1CEMENTO UG 42,5 KG | B26: 7199990001 | C26: CONSUMOS SEMIELBORAD | D26: CEMENTOUG1 | E26: CEMENTO UG 42,5 KG | F26: CEMENTO UG 42,5 KG | G26: 9 | H26: Cemento UG | J26: 700100 | K26: CEMENTO BIG BAG 1,5 TONELADAS
A27: =B27&D27&F27 -> 736005030222000000004CEMENTO UG 25 KG | B27: 7360050302 | C27: CTO BOLSAS IMP | D27: 22000000004 | E27: CEMENTO UG 25 KG | F27: CEMENTO UG 25 KG | G27: 10 | H27: Sacos | J27: 700064 | K27: FIBROCEMENTO
A28: =B28&D28&F28 -> 7199990001CEMENTOUG1CEMENTO UG 25 KG | B28: 7199990001 | C28: CONSUMOS SEMIELBORAD | D28: CEMENTOUG1 | E28: CEMENTO UG 25 KG | F28: CEMENTO UG 25 KG | G28: 10 | H28: Cemento UG | J28: 700120 | K28: COMBUSTIBLES ALTERNOS
A29: =B29&D29&F29 -> 736005030222000000006CEMENTO UG 42,5 KG | B29: 7360050302 | C29: CTO BOLSAS IMP | D29: 22000000006 | E29: CEMENTO UG 42,5 KG | F29: CEMENTO UG 42,5 KG | G29: 9 | H29: Sacos | J29: 700056 | K29: Cementos
A30: =B30&D30&F30 -> 7495700001REGALIASAdiciones | B30: 7495700001 | C30: SERVICIOS DE EXPLOTA | D30: REGALIAS | E30: CALIZA PARA ADICIONES | F30: Adiciones | G30: 2 | H30: Regalías
A31: =B31&D31&F31 -> 7199990001CEMENTO UG TPCEMENTO TOPEX 50 KG | B31: 7199990001 | C31: CONSUMOS SEMIELBORAD | D31: CEMENTO UG TP | E31: CEMENTO TOPEX 50 KG | F31: CEMENTO TOPEX 50 KG | G31: 14 | H31: Cemento UG TP
A32: =B32&D32&F32 -> 736005030222000000041CEMENTO TOPEX 50 KG | B32: 7360050302 | C32: CTO BOLSAS IMP | D32: 22000000041 | E32: CEMENTO TOPEX 50 KG | F32: CEMENTO TOPEX 50 KG | G32: 14 | H32: Sacos
A33: =B33&D33&F33 -> 7355250320CUERPOS MOLEDORESMolienda de Crudo | B33: 7355250320 | C33: RTOS VARIA IMPO | D33: CUERPOS MOLEDORES | E33: HARINA CRUDA | F33: Molienda de Crudo | G33: 3 | H33: Cuerpos Moledores
A34: =B34&D34&F34 -> 7355250321LAMINASMolienda de Crudo | B34: 7355250321 | C34: RTOS VARIA IMPO | D34: LAMINAS | E34: HARINA CRUDA | F34: Molienda de Crudo | G34: 3 | H34: Láminas
A35: =B35&D35&F35 -> 7355250322ANILLOS, TAPAS Y SEPARADORESMolienda de Crudo | B35: 7355250322 | C35: RTOS VARIA IMPO | D35: ANILLOS, TAPAS Y SEPARADORES | E35: HARINA CRUDA | F35: Molienda de Crudo | G35: 3 | H35: Anillos, Tapas y Separadores
A36: =B36&D36&F36 -> 7355250320CUERPOS MOLEDORES Y LAMINASMolienda de Carbón | B36: 7355250320 | C36: RTOS VARIA IMPO | D36: CUERPOS MOLEDORES Y LAMINAS | E36: CARBON MOLIDO | F36: Molienda de Carbón | G36: 4 | H36: Cuerpos Moledores y Láminas
A37: =B37&D37&F37 -> 7355250321DESCARGUE FINOS CARBONMolienda de Carbón | B37: 7355250321 | C37: RTOS VARIA IMPO | D37: DESCARGUE FINOS CARBON | E37: FINOS DE CARBON | F37: Molienda de Carbón | G37: 4 | H37: Descargue Finos Carbón
A38: =B38&D38&F38 -> 7355250320DUCTOSClinkerización | B38: 7355250320 | C38: RTOS VARIA IMPO | D38: DUCTOS | E38: CLINKER | F38: Clinkerización | G38: 5 | H38: Ductos
A39: =B39&D39&F39 -> 7355250321ENFRIADORClinkerización | B39: 7355250321 | C39: RTOS VARIA IMPO | D39: ENFRIADOR | E39: CLINKER | F39: Clinkerización | G39: 5 | H39: Enfriador
A40: =B40&D40&F40 -> 7355250323SELLADOClinkerización | B40: 7355250323 | C40: RTOS VARIA IMPO | D40: SELLADO | E40: CLINKER | F40: Clinkerización | G40: 5 | H40: Sellado
...

Sheet Base
A1: Clase de coste | B1: Denom.clase de coste | C1: Valor/mon.inf. | D1: Cantidad total reg. | E1: Ud. cantidad contab. | F1: Clase cta. de contrapartida | G1: Cta.contrapartida | H1: Denominacion cuenta contrapartida | I1: Centro | J1: Material | K1: Orden | L1: Período | M1: Texto breve de material | N1: Fe.contabilización | O1: Fecha de documento | P1: Mat2 | Q1: Proceso | R1: ORD | S1: CN | T1: Tipo | U1: Arrastre
A2: 7105040101 | B2: MP CORRECT HIERO NAL | C2: =Datos!$I$48*D2+Datos!$H$90*Base!D2 -> 8.8179093e+08 | D2: =Datos!$H$263*Datos!$H$169*(1+Datos!$H$213) -> 2931.225 | E2: T | F2: M | G2: 1405040101 | H2: IN CORRECT HIERO NAL | I2: EC01 | J2: CORRHIERR | K2: 700000 | L2: 1 | M2: CORRECTOR DE HIERRO | P2: =VLOOKUP(K2,Maestro!J:K,2,0) -> HARINA CRUDA | Q2: =VLOOKUP(P2,Maestro!E:F,2,0) -> Molienda de Crudo | R2: =VLOOKUP(P2,ORD!$A:$C,3,0) -> 3 | S2: =A2&J2&Q2 -> 7105040101CORRHIERRMolienda de Crudo | T2: =IFERROR(VLOOKUP(S2,Maestro!$A:$H,8,0),"Producción") -> Mineral de Hierro | U2: Clinker
A3: 7105040101 | B3: MP CORRECT HIERO NAL | C3: =Datos!$H$49*D3+Datos!$H$90*D3 -> 85178561 | D3: =Datos!$H$263*Datos!$H$170*(1+Datos!$H$214) -> 499.87575 | E3: T | F3: M | G3: 1405040101 | H3: IN CORRECT HIERO NAL | I3: EC01 | J3: CALAMINA1 | K3: 700000 | L3: 1 | M3: CALAMINA | P3: =VLOOKUP(K3,Maestro!J:K,2,0) -> HARINA CRUDA | Q3: =VLOOKUP(P3,Maestro!E:F,2,0) -> Molienda de Crudo | R3: =VLOOKUP(P3,ORD!$A:$C,3,0) -> 3 | S3: =A3&J3&Q3 -> 7105040101CALAMINA1Molienda de Crudo | T3: =IFERROR(VLOOKUP(S3,Maestro!$A:$H,8,0),"Producción") -> Mineral de Hierro | U3: Clinker
A4: 7105330101 | B4: CTO. MP CALIZAS NAL | D4: =Datos!$H$263*Datos!$H$168*(1+Datos!$H$210) -> 24130.92 | E4: T | F4: M | G4: 1405330101 | H4: INV. CALIZAS NAL | I4: EC01 | J4: CALIZATRI | K4: 700000 | L4: 1 | M4: CALIZA TRITURADA | P4: =VLOOKUP(K4,Maestro!J:K,2,0) -> HARINA CRUDA | Q4: =VLOOKUP(P4,Maestro!E:F,2,0) -> Molienda de Crudo | R4: =VLOOKUP(P4,ORD!$A:$C,3,0) -> 3 | S4: =A4&J4&Q4 -> 7105330101CALIZATRIMolienda de Crudo | T4: =IFERROR(VLOOKUP(S4,Maestro!$A:$H,8,0),"Producción") -> Caliza | U4: Clinker
A5: 7105330101 | B5: CTO. MP CALIZAS NAL | D5: =Datos!$H$263*Datos!$H$167*(1+Datos!$H$212) -> 109733.16 | E5: T | F5: M | G5: 1405330101 | H5: INV. CALIZAS NAL | I5: EC01 | J5: MEZCPREHO | K5: 700000 | L5: 1 | M5: MEZCLA PREHOMO | P5: =VLOOKUP(K5,Maestro!J:K,2,0) -> HARINA CRUDA | Q5: =VLOOKUP(P5,Maestro!E:F,2,0) -> Molienda de Crudo | R5: =VLOOKUP(P5,ORD!$A:$C,3,0) -> 3 | S5: =A5&J5&Q5 -> 7105330101MEZCPREHOMolienda de Crudo | T5: =IFERROR(VLOOKUP(S5,Maestro!$A:$H,8,0),"Producción") -> Prehomo | U5: Clinker
A6: 7999999995 | B6: TRASLADO DE COSTOS | D6: =-Datos!$H$263 -> -132000 | E6: T | F6: M | G6: 1410900101 | H6: INV. SEMIELABORADO | I6: EC01 | J6: HARINACRUD | K6: 700000 | L6: 1 | M6: HARINA CRUDA | P6: =VLOOKUP(K6,Maestro!J:K,2,0) -> HARINA CRUDA | Q6: =VLOOKUP(P6,Maestro!E:F,2,0) -> Molienda de Crudo | R6: =VLOOKUP(P6,ORD!$A:$C,3,0) -> 3 | S6: =A6&J6&Q6 -> 7999999995HARINACRUDMolienda de Crudo | T6: =IFERROR(VLOOKUP(S6,Maestro!$A:$H,8,0),"Producción") -> Producción | U6: Clinker
A7: 7355250320 | B7: RTOS VARIA IMPO | C7: =Datos!$H$112*D7 -> 22058455 | D7: =Datos!$H$263 -> 132000 | I7: EC01 | J7: CUERPOS MOLEDORES | K7: 700000 | L7: 1 | M7: HARINA CRUDA | P7: =VLOOKUP(K7,Maestro!J:K,2,0) -> HARINA CRUDA | Q7: =VLOOKUP(P7,Maestro!E:F,2,0) -> Molienda de Crudo | R7: =VLOOKUP(P7,ORD!$A:$C,3,0) -> 3 | S7: =A7&J7&Q7 -> 7355250320CUERPOS MOLEDORESMolienda de Crudo | T7: =IFERROR(VLOOKUP(S7,Maestro!$A:$H,8,0),"Producción") -> Cuerpos Moledores | U7: Clinker
A8: 7355250321 | B8: RTOS VARIA IMPO | C8: =Datos!$H$114*D8 -> 15824544 | D8: =Datos!$H$263 -> 132000 | I8: EC01 | J8: LAMINAS | K8: 700000 | L8: 1 | M8: HARINA CRUDA | P8: =VLOOKUP(K8,Maestro!J:K,2,0) -> HARINA CRUDA | Q8: =VLOOKUP(P8,Maestro!E:F,2,0) -> Molienda de Crudo | R8: =VLOOKUP(P8,ORD!$A:$C,3,0) -> 3 | S8: =A8&J8&Q8 -> 7355250321LAMINASMolienda de Crudo | T8: =IFERROR(VLOOKUP(S8,Maestro!$A:$H,8,0),"Producción") -> Láminas | U8: Clinker
A9: 7355250322 | B9: RTOS VARIA IMPO | C9: =Datos!$H$118*D9 -> 65828938 | D9: =Datos!$H$263 -> 132000 | I9: EC01 | J9: ANILLOS, TAPAS Y SEPARADORES | K9: 700000 | L9: 1 | M9: HARINA CRUDA | P9: =VLOOKUP(K9,Maestro!J:K,2,0) -> HARINA CRUDA | Q9: =VLOOKUP(P9,Maestro!E:F,2,0) -> Molienda de Crudo | R9: =VLOOKUP(P9,ORD!$A:$C,3,0) -> 3 | S9: =A9&J9&Q9 -> 7355250322ANILLOS, TAPAS Y SEPARADORESMolienda de Crudo | T9: =IFERROR(VLOOKUP(S9,Maestro!$A:$H,8,0),"Producción") -> Anillos, Tapas y Separadores | U9: Clinker
A10: 7105040101 | B10: MP CORRECT HIERO NAL | C10: =Datos!$I$48*D10+Datos!$I$90*Base!D10 -> 8.9005767e+08 | D10: =Datos!$I$263*Datos!$I$169*(1+Datos!$I$213) -> 2958.9828 | E10: T | F10: M | G10: 1405040101 | H10: IN CORRECT HIERO NAL | I10: EC01 | J10: CORRHIERR | K10: 700000 | L10: 2 | M10: CORRECTOR DE HIERRO | P10: =VLOOKUP(K10,Maestro!J:K,2,0) -> HARINA CRUDA | Q10: =VLOOKUP(P10,Maestro!E:F,2,0) -> Molienda de Crudo | R10: =VLOOKUP(P10,ORD!$A:$C,3,0) -> 3 | S10: =A10&J10&Q10 -> 7105040101CORRHIERRMolienda de Crudo | T10: =IFERROR(VLOOKUP(S10,Maestro!$A:$H,8,0),"Producción") -> Mineral de Hierro | U10: Clinker
A11: 7105040101 | B11: MP CORRECT HIERO NAL | C11: =Datos!$I$49*D11+Datos!$I$90*D11 -> 85970928 | D11: =Datos!$I$263*Datos!$I$170*(1+Datos!$I$214) -> 504.60942 | E11: T | F11: M | G11: 1405040101 | H11: IN CORRECT HIERO NAL | I11: EC01 | J11: CALAMINA1 | K11: 700000 | L11: 2 | M11: CALAMINA | P11: =VLOOKUP(K11,Maestro!J:K,2,0) -> HARINA CRUDA | Q11: =VLOOKUP(P11,Maestro!E:F,2,0) -> Molienda de Crudo | R11: =VLOOKUP(P11,ORD!$A:$C,3,0) -> 3 | S11: =A11&J11&Q11 -> 7105040101CALAMINA1Molienda de Crudo | T11: =IFERROR(VLOOKUP(S11,Maestro!$A:$H,8,0),"Producción") -> Mineral de Hierro | U11: Clinker
A12: 7105330101 | B12: CTO. MP CALIZAS NAL | D12: =Datos!$I$263*Datos!$I$168*(1+Datos!$I$210) -> 24359.432 | E12: T | F12: M | G12: 1405330101 | H12: INV. CALIZAS NAL | I12: EC01 | J12: CALIZATRI | K12: 700000 | L12: 2 | M12: CALIZA TRITURADA | P12: =VLOOKUP(K12,Maestro!J:K,2,0) -> HARINA CRUDA | Q12: =VLOOKUP(P12,Maestro!E:F,2,0) -> Molienda de Crudo | R12: =VLOOKUP(P12,ORD!$A:$C,3,0) -> 3 | S12: =A12&J12&Q12 -> 7105330101CALIZATRIMolienda de Crudo | T12: =IFERROR(VLOOKUP(S12,Maestro!$A:$H,8,0),"Producción") -> Caliza | U12: Clinker
A13: 7105330101 | B13: CTO. MP CALIZAS NAL | D13: =Datos!$I$263*Datos!$I$167*(1+Datos!$I$212) -> 110772.3 | E13: T | F13: M | G13: 1405330101 | H13: INV. CALIZAS NAL | I13: EC01 | J13: MEZCPREHO | K13: 700000 | L13: 2 | M13: MEZCLA PREHOMO | P13: =VLOOKUP(K13,Maestro!J:K,2,0) -> HARINA CRUDA | Q13: =VLOOKUP(P13,Maestro!E:F,2,0) -> Molienda de Crudo | R13: =VLOOKUP(P13,ORD!$A:$C,3,0) -> 3 | S13: =A13&J13&Q13 -> 7105330101MEZCPREHOMolienda de Crudo | T13: =IFERROR(VLOOKUP(S13,Maestro!$A:$H,8,0),"Producción") -> Prehomo | U13: Clinker
A14: 7999999995 | B14: TRASLADO DE COSTOS | D14: =-Datos!$I$263 -> -133250 | E14: T | F14: M | G14: 1410900101 | H14: INV. SEMIELABORADO | I14: EC01 | J14: HARINACRUD | K14: 700000 | L14: 2 | M14: HARINA CRUDA | P14: =VLOOKUP(K14,Maestro!J:K,2,0) -> HARINA CRUDA | Q14: =VLOOKUP(P14,Maestro!E:F,2,0) -> Molienda de Crudo | R14: =VLOOKUP(P14,ORD!$A:$C,3,0) -> 3 | S14: =A14&J14&Q14 -> 7999999995HARINACRUDMolienda de Crudo | T14: =IFERROR(VLOOKUP(S14,Maestro!$A:$H,8,0),"Producción") -> Producción | U14: Clinker
A15: 7355250320 | B15: RTOS VARIA IMPO | C15: =Datos!$I$112*D15 -> 22267342 | D15: =Datos!$I$263 -> 133250 | I15: EC01 | J15: CUERPOS MOLEDORES | K15: 700000 | L15: 2 | M15: HARINA CRUDA | P15: =VLOOKUP(K15,Maestro!J:K,2,0) -> HARINA CRUDA | Q15: =VLOOKUP(P15,Maestro!E:F,2,0) -> Molienda de Crudo | R15: =VLOOKUP(P15,ORD!$A:$C,3,0) -> 3 | S15: =A15&J15&Q15 -> 7355250320CUERPOS MOLEDORESMolienda de Crudo | T15: =IFERROR(VLOOKUP(S15,Maestro!$A:$H,8,0),"Producción") -> Cuerpos Moledores | U15: Clinker
A16: 7355250321 | B16: RTOS VARIA IMPO | C16: =Datos!$I$114*D16 -> 15974398 | D16: =Datos!$I$263 -> 133250 | I16: EC01 | J16: LAMINAS | K16: 700000 | L16: 2 | M16: HARINA CRUDA | P16: =VLOOKUP(K16,Maestro!J:K,2,0) -> HARINA CRUDA | Q16: =VLOOKUP(P16,Maestro!E:F,2,0) -> Molienda de Crudo | R16: =VLOOKUP(P16,ORD!$A:$C,3,0) -> 3 | S16: =A16&J16&Q16 -> 7355250321LAMINASMolienda de Crudo | T16: =IFERROR(VLOOKUP(S16,Maestro!$A:$H,8,0),"Producción") -> Láminas | U16: Clinker
A17: 7355250322 | B17: RTOS VARIA IMPO | C17: =Datos!$I$118*D17 -> 66452318 | D17: =Datos!$I$263 -> 133250 | I17: EC01 | J17: ANILLOS, TAPAS Y SEPARADORES | K17: 700000 | L17: 2 | M17: HARINA CRUDA | P17: =VLOOKUP(K17,Maestro!J:K,2,0) -> HARINA CRUDA | Q17: =VLOOKUP(P17,Maestro!E:F,2,0) -> Molienda de Crudo | R17: =VLOOKUP(P17,ORD!$A:$C,3,0) -> 3 | S17: =A17&J17&Q17 -> 7355250322ANILLOS, TAPAS Y SEPARADORESMolienda de Crudo | T17: =IFERROR(VLOOKUP(S17,Maestro!$A:$H,8,0),"Producción") -> Anillos, Tapas y Separadores | U17: Clinker
A18: 7105040101 | B18: MP CORRECT HIERO NAL | C18: =Datos!$I$48*D18+Datos!$J$90*Base!D18 -> 6.3492394e+08 | D18: =Datos!$J$263*Datos!$J$169*(1+Datos!$J$213) -> 2109.5938 | E18: T | F18: M | G18: 1405040101 | H18: IN CORRECT HIERO NAL | I18: EC01 | J18: CORRHIERR | K18: 700000 | L18: 3 | M18: CORRECTOR DE HIERRO | P18: =VLOOKUP(K18,Maestro!J:K,2,0) -> HARINA CRUDA | Q18: =VLOOKUP(P18,Maestro!E:F,2,0) -> Molienda de Crudo | R18: =VLOOKUP(P18,ORD!$A:$C,3,0) -> 3 | S18: =A18&J18&Q18 -> 7105040101CORRHIERRMolienda de Crudo | T18: =IFERROR(VLOOKUP(S18,Maestro!$A:$H,8,0),"Producción") -> Mineral de Hierro | U18: Clinker
A19: 7105040101 | B19: MP CORRECT HIERO NAL | C19: =Datos!$J$49*D19+Datos!$J$90*D19 -> 61354199 | D19: =Datos!$J$263*Datos!$J$170*(1+Datos!$J$214) -> 359.75906 | E19: T | F19: M | G19: 1405040101 | H19: IN CORRECT HIERO NAL | I19: EC01 | J19: CALAMINA1 | K19: 700000 | L19: 3 | M19: CALAMINA | P19: =VLOOKUP(K19,Maestro!J:K,2,0) -> HARINA CRUDA | Q19: =VLOOKUP(P19,Maestro!E:F,2,0) -> Molienda de Crudo | R19: =VLOOKUP(P19,ORD!$A:$C,3,0) -> 3 | S19: =A19&J19&Q19 -> 7105040101CALAMINA1Molienda de Crudo | T19: =IFERROR(VLOOKUP(S19,Maestro!$A:$H,8,0),"Producción") -> Mineral de Hierro | U19: Clinker
A20: 7105330101 | B20: CTO. MP CALIZAS NAL | D20: =Datos!$J$263*Datos!$J$168*(1+Datos!$J$210) -> 17366.95 | E20: T | F20: M | G20: 1405330101 | H20: INV. CALIZAS NAL | I20: EC01 | J20: CALIZATRI | K20: 700000 | L20: 3 | M20: CALIZA TRITURADA | P20: =VLOOKUP(K20,Maestro!J:K,2,0) -> HARINA CRUDA | Q20: =VLOOKUP(P20,Maestro!E:F,2,0) -> Molienda de Crudo | R20: =VLOOKUP(P20,ORD!$A:$C,3,0) -> 3 | S20: =A20&J20&Q20 -> 7105330101CALIZATRIMolienda de Crudo | T20: =IFERROR(VLOOKUP(S20,Maestro!$A:$H,8,0),"Producción") -> Caliza | U20: Clinker
A21: 7105330101 | B21: CTO. MP CALIZAS NAL | D21: =Datos!$J$263*Datos!$J$167*(1+Datos!$J$212) -> 78974.624 | E21: T | F21: M | G21: 1405330101 | H21: INV. CALIZAS NAL | I21: EC01 | J21: MEZCPREHO | K21: 700000 | L21: 3 | M21: MEZCLA PREHOMO | P21: =VLOOKUP(K21,Maestro!J:K,2,0) -> HARINA CRUDA | Q21: =VLOOKUP(P21,Maestro!E:F,2,0) -> Molienda de Crudo | R21: =VLOOKUP(P21,ORD!$A:$C,3,0) -> 3 | S21: =A21&J21&Q21 -> 7105330101MEZCPREHOMolienda de Crudo | T21: =IFERROR(VLOOKUP(S21,Maestro!$A:$H,8,0),"Producción") -> Prehomo | U21: Clinker
A22: 7999999995 | B22: TRASLADO DE COSTOS | D22: =-Datos!$J$263 -> -95000 | E22: T | F22: M | G22: 1410900101 | H22: INV. SEMIELABORADO | I22: EC01 | J22: HARINACRUD | K22: 700000 | L22: 3 | M22: HARINA CRUDA | P22: =VLOOKUP(K22,Maestro!J:K,2,0) -> HARINA CRUDA | Q22: =VLOOKUP(P22,Maestro!E:F,2,0) -> Molienda de Crudo | R22: =VLOOKUP(P22,ORD!$A:$C,3,0) -> 3 | S22: =A22&J22&Q22 -> 7999999995HARINACRUDMolienda de Crudo | T22: =IFERROR(VLOOKUP(S22,Maestro!$A:$H,8,0),"Producción") -> Producción | U22: Clinker
A23: 7355250320 | B23: RTOS VARIA IMPO | C23: =Datos!$J$112*D23 -> 15875404 | D23: =Datos!$J$263 -> 95000 | I23: EC01 | J23: CUERPOS MOLEDORES | K23: 700000 | L23: 3 | M23: HARINA CRUDA | P23: =VLOOKUP(K23,Maestro!J:K,2,0) -> HARINA CRUDA | Q23: =VLOOKUP(P23,Maestro!E:F,2,0) -> Molienda de Crudo | R23: =VLOOKUP(P23,ORD!$A:$C,3,0) -> 3 | S23: =A23&J23&Q23 -> 7355250320CUERPOS MOLEDORESMolienda de Crudo | T23: =IFERROR(VLOOKUP(S23,Maestro!$A:$H,8,0),"Producción") -> Cuerpos Moledores | U23: Clinker
A24: 7355250321 | B24: RTOS VARIA IMPO | C24: =Datos!$J$114*D24 -> 11388876 | D24: =Datos!$J$263 -> 95000 | I24: EC01 | J24: LAMINAS | K24: 700000 | L24: 3 | M24: HARINA CRUDA | P24: =VLOOKUP(K24,Maestro!J:K,2,0) -> HARINA CRUDA | Q24: =VLOOKUP(P24,Maestro!E:F,2,0) -> Molienda de Crudo | R24: =VLOOKUP(P24,ORD!$A:$C,3,0) -> 3 | S24: =A24&J24&Q24 -> 7355250321LAMINASMolienda de Crudo | T24: =IFERROR(VLOOKUP(S24,Maestro!$A:$H,8,0),"Producción") -> Láminas | U24: Clinker
A25: 7355250322 | B25: RTOS VARIA IMPO | C25: =Datos!$J$118*D25 -> 47376887 | D25: =Datos!$J$263 -> 95000 | I25: EC01 | J25: ANILLOS, TAPAS Y SEPARADORES | K25: 700000 | L25: 3 | M25: HARINA CRUDA | P25: =VLOOKUP(K25,Maestro!J:K,2,0) -> HARINA CRUDA | Q25: =VLOOKUP(P25,Maestro!E:F,2,0) -> Molienda de Crudo | R25: =VLOOKUP(P25,ORD!$A:$C,3,0) -> 3 | S25: =A25&J25&Q25 -> 7355250322ANILLOS, TAPAS Y SEPARADORESMolienda de Crudo | T25: =IFERROR(VLOOKUP(S25,Maestro!$A:$H,8,0),"Producción") -> Anillos, Tapas y Separadores | U25: Clinker
A26: 7105040101 | B26: MP CORRECT HIERO NAL | C26: =Datos!$I$48*D26+Datos!$K$90*Base!D26 -> 6.5164811e+08 | D26: =Datos!$K$263*Datos!$K$169*(1+Datos!$K$213) -> 2165.1094 | E26: T | F26: M | G26: 1405040101 | H26: IN CORRECT HIERO NAL | I26: EC01 | J26: CORRHIERR | K26: 700000 | L26: 4 | M26: CORRECTOR DE HIERRO | P26: =VLOOKUP(K26,Maestro!J:K,2,0) -> HARINA CRUDA | Q26: =VLOOKUP(P26,Maestro!E:F,2,0) -> Molienda de Crudo | R26: =VLOOKUP(P26,ORD!$A:$C,3,0) -> 3 | S26: =A26&J26&Q26 -> 7105040101CORRHIERRMolienda de Crudo | T26: =IFERROR(VLOOKUP(S26,Maestro!$A:$H,8,0),"Producción") -> Mineral de Hierro | U26: Clinker
A27: 7105040101 | B27: MP CORRECT HIERO NAL | C27: =Datos!$K$49*D27+Datos!$K$90*D27 -> 62971452 | D27: =Datos!$K$263*Datos!$K$170*(1+Datos!$K$214) -> 369.22641 | E27: T | F27: M | G27: 1405040101 | H27: IN CORRECT HIERO NAL | I27: EC01 | J27: CALAMINA1 | K27: 700000 | L27: 4 | M27: CALAMINA | P27: =VLOOKUP(K27,Maestro!J:K,2,0) -> HARINA CRUDA | Q27: =VLOOKUP(P27,Maestro!E:F,2,0) -> Molienda de Crudo | R27: =VLOOKUP(P27,ORD!$A:$C,3,0) -> 3 | S27: =A27&J27&Q27 -> 7105040101CALAMINA1Molienda de Crudo | T27: =IFERROR(VLOOKUP(S27,Maestro!$A:$H,8,0),"Producción") -> Mineral de Hierro | U27: Clinker
A28: 7105330101 | B28: CTO. MP CALIZAS NAL | D28: =Datos!$K$263*Datos!$K$168*(1+Datos!$K$210) -> 17823.975 | E28: T | F28: M | G28: 1405330101 | H28: INV. CALIZAS NAL | I28: EC01 | J28: CALIZATRI | K28: 700000 | L28: 4 | M28: CALIZA TRITURADA | P28: =VLOOKUP(K28,Maestro!J:K,2,0) -> HARINA CRUDA | Q28: =VLOOKUP(P28,Maestro!E:F,2,0) -> Molienda de Crudo | R28: =VLOOKUP(P28,ORD!$A:$C,3,0) -> 3 | S28: =A28&J28&Q28 -> 7105330101CALIZATRIMolienda de Crudo | T28: =IFERROR(VLOOKUP(S28,Maestro!$A:$H,8,0),"Producción") -> Caliza | U28: Clinker
A29: 7105330101 | B29: CTO. MP CALIZAS NAL | D29: =Datos!$K$263*Datos!$K$167*(1+Datos!$K$212) -> 81052.904 | E29: T | F29: M | G29: 1405330101 | H29: INV. CALIZAS NAL | I29: EC01 | J29: MEZCPREHO | K29: 700000 | L29: 4 | M29: MEZCLA PREHOMO | P29: =VLOOKUP(K29,Maestro!J:K,2,0) -> HARINA CRUDA | Q29: =VLOOKUP(P29,Maestro!E:F,2,0) -> Molienda de Crudo | R29: =VLOOKUP(P29,ORD!$A:$C,3,0) -> 3 | S29: =A29&J29&Q29 -> 7105330101MEZCPREHOMolienda de Crudo | T29: =IFERROR(VLOOKUP(S29,Maestro!$A:$H,8,0),"Producción") -> Prehomo | U29: Clinker
A30: 7999999995 | B30: TRASLADO DE COSTOS | D30: =-Datos!$K$263 -> -97500 | E30: T | F30: M | G30: 1410900101 | H30: INV. SEMIELABORADO | I30: EC01 | J30: HARINACRUD | K30: 700000 | L30: 4 | M30: HARINA CRUDA | P30: =VLOOKUP(K30,Maestro!J:K,2,0) -> HARINA CRUDA | Q30: =VLOOKUP(P30,Maestro!E:F,2,0) -> Molienda de Crudo | R30: =VLOOKUP(P30,ORD!$A:$C,3,0) -> 3 | S30: =A30&J30&Q30 -> 7999999995HARINACRUDMolienda de Crudo | T30: =IFERROR(VLOOKUP(S30,Maestro!$A:$H,8,0),"Producción") -> Producción | U30: Clinker
A31: 7355250320 | B31: RTOS VARIA IMPO | C31: =Datos!$K$112*D31 -> 16293177 | D31: =Datos!$K$263 -> 97500 | I31: EC01 | J31: CUERPOS MOLEDORES | K31: 700000 | L31: 4 | M31: HARINA CRUDA | P31: =VLOOKUP(K31,Maestro!J:K,2,0) -> HARINA CRUDA | Q31: =VLOOKUP(P31,Maestro!E:F,2,0) -> Molienda de Crudo | R31: =VLOOKUP(P31,ORD!$A:$C,3,0) -> 3 | S31: =A31&J31&Q31 -> 7355250320CUERPOS MOLEDORESMolienda de Crudo | T31: =IFERROR(VLOOKUP(S31,Maestro!$A:$H,8,0),"Producción") -> Cuerpos Moledores | U31: Clinker
A32: 7355250321 | B32: RTOS VARIA IMPO | C32: =Datos!$K$114*D32 -> 11688584 | D32: =Datos!$K$263 -> 97500 | I32: EC01 | J32: LAMINAS | K32: 700000 | L32: 4 | M32: HARINA CRUDA | P32: =VLOOKUP(K32,Maestro!J:K,2,0) -> HARINA CRUDA | Q32: =VLOOKUP(P32,Maestro!E:F,2,0) -> Molienda de Crudo | R32: =VLOOKUP(P32,ORD!$A:$C,3,0) -> 3 | S32: =A32&J32&Q32 -> 7355250321LAMINASMolienda de Crudo | T32: =IFERROR(VLOOKUP(S32,Maestro!$A:$H,8,0),"Producción") -> Láminas | U32: Clinker
A33: 7355250322 | B33: RTOS VARIA IMPO | C33: =Datos!$K$118*D33 -> 48623647 | D33: =Datos!$K$263 -> 97500 | I33: EC01 | J33: ANILLOS, TAPAS Y SEPARADORES | K33: 700000 | L33: 4 | M33: HARINA CRUDA | P33: =VLOOKUP(K33,Maestro!J:K,2,0) -> HARINA CRUDA | Q33: =VLOOKUP(P33,Maestro!E:F,2,0) -> Molienda de Crudo | R33: =VLOOKUP(P33,ORD!$A:$C,3,0) -> 3 | S33: =A33&J33&Q33 -> 7355250322ANILLOS, TAPAS Y SEPARADORESMolienda de Crudo | T33: =IFERROR(VLOOKUP(S33,Maestro!$A:$H,8,0),"Producción") -> Anillos, Tapas y Separadores | U33: Clinker
A34: 7105040101 | B34: MP CORRECT HIERO NAL | C34: =Datos!$I$48*D34+Datos!$L$90*Base!D34 -> 9.8509076e+08 | D34: =Datos!$L$263*Datos!$L$169*(1+Datos!$L$213) -> 3275.4219 | E34: T | F34: M | G34: 1405040101 | H34: IN CORRECT HIERO NAL | I34: EC01 | J34: CORRHIERR | K34: 700000 | L34: 5 | M34: CORRECTOR DE HIERRO | P34: =VLOOKUP(K34,Maestro!J:K,2,0) -> HARINA CRUDA | Q34: =VLOOKUP(P34,Maestro!E:F,2,0) -> Molienda de Crudo | R34: =VLOOKUP(P34,ORD!$A:$C,3,0) -> 3 | S34: =A34&J34&Q34 -> 7105040101CORRHIERRMolienda de Crudo | T34: =IFERROR(VLOOKUP(S34,Maestro!$A:$H,8,0),"Producción") -> Mineral de Hierro | U34: Clinker
A35: 7105040101 | B35: MP CORRECT HIERO NAL | C35: =Datos!$L$49*D35+Datos!$L$90*D35 -> 95139013 | D35: =Datos!$L$263*Datos!$L$170*(1+Datos!$L$214) -> 558.57328 | E35: T | F35: M | G35: 1405040101 | H35: IN CORRECT HIERO NAL | I35: EC01 | J35: CALAMINA1 | K35: 700000 | L35: 5 | M35: CALAMINA | P35: =VLOOKUP(K35,Maestro!J:K,2,0) -> HARINA CRUDA | Q35: =VLOOKUP(P35,Maestro!E:F,2,0) -> Molienda de Crudo | R35: =VLOOKUP(P35,ORD!$A:$C,3,0) -> 3 | S35: =A35&J35&Q35 -> 7105040101CALAMINA1Molienda de Crudo | T35: =IFERROR(VLOOKUP(S35,Maestro!$A:$H,8,0),"Producción") -> Mineral de Hierro | U35: Clinker
A36: 7105330101 | B36: CTO. MP CALIZAS NAL | D36: =Datos!$L$263*Datos!$L$168*(1+Datos!$L$210) -> 26964.475 | E36: T | F36: M | G36: 1405330101 | H36: INV. CALIZAS NAL | I36: EC01 | J36: CALIZATRI | K36: 700000 | L36: 5 | M36: CALIZA TRITURADA | P36: =VLOOKUP(K36,Maestro!J:K,2,0) -> HARINA CRUDA | Q36: =VLOOKUP(P36,Maestro!E:F,2,0) -> Molienda de Crudo | R36: =VLOOKUP(P36,ORD!$A:$C,3,0) -> 3 | S36: =A36&J36&Q36 -> 7105330101CALIZATRIMolienda de Crudo | T36: =IFERROR(VLOOKUP(S36,Maestro!$A:$H,8,0),"Producción") -> Caliza | U36: Clinker
A37: 7105330101 | B37: CTO. MP CALIZAS NAL | D37: =Datos!$L$263*Datos!$L$167*(1+Datos!$L$212) -> 122618.5 | E37: T | F37: M | G37: 1405330101 | H37: INV. CALIZAS NAL | I37: EC01 | J37: MEZCPREHO | K37: 700000 | L37: 5 | M37: MEZCLA PREHOMO | P37: =VLOOKUP(K37,Maestro!J:K,2,0) -> HARINA CRUDA | Q37: =VLOOKUP(P37,Maestro!E:F,2,0) -> Molienda de Crudo | R37: =VLOOKUP(P37,ORD!$A:$C,3,0) -> 3 | S37: =A37&J37&Q37 -> 7105330101MEZCPREHOMolienda de Crudo | T37: =IFERROR(VLOOKUP(S37,Maestro!$A:$H,8,0),"Producción") -> Prehomo | U37: Clinker
A38: 7999999995 | B38: TRASLADO DE COSTOS | D38: =-Datos!$L$263 -> -147500 | E38: T | F38: M | G38: 1410900101 | H38: INV. SEMIELABORADO | I38: EC01 | J38: HARINACRUD | K38: 700000 | L38: 5 | M38: HARINA CRUDA | P38: =VLOOKUP(K38,Maestro!J:K,2,0) -> HARINA CRUDA | Q38: =VLOOKUP(P38,Maestro!E:F,2,0) -> Molienda de Crudo | R38: =VLOOKUP(P38,ORD!$A:$C,3,0) -> 3 | S38: =A38&J38&Q38 -> 7999999995HARINACRUDMolienda de Crudo | T38: =IFERROR(VLOOKUP(S38,Maestro!$A:$H,8,0),"Producción") -> Producción | U38: Clinker
A39: 7355250320 | B39: RTOS VARIA IMPO | C39: =Datos!$L$112*D39 -> 24648653 | D39: =Datos!$L$263 -> 147500 | I39: EC01 | J39: CUERPOS MOLEDORES | K39: 700000 | L39: 5 | M39: HARINA CRUDA | P39: =VLOOKUP(K39,Maestro!J:K,2,0) -> HARINA CRUDA | Q39: =VLOOKUP(P39,Maestro!E:F,2,0) -> Molienda de Crudo | R39: =VLOOKUP(P39,ORD!$A:$C,3,0) -> 3 | S39: =A39&J39&Q39 -> 7355250320CUERPOS MOLEDORESMolienda de Crudo | T39: =IFERROR(VLOOKUP(S39,Maestro!$A:$H,8,0),"Producción") -> Cuerpos Moledores | U39: Clinker
A40: 7355250321 | B40: RTOS VARIA IMPO | C40: =Datos!$L$114*D40 -> 17682729 | D40: =Datos!$L$263 -> 147500 | I40: EC01 | J40: LAMINAS | K40: 700000 | L40: 5 | M40: HARINA CRUDA | P40: =VLOOKUP(K40,Maestro!J:K,2,0) -> HARINA CRUDA | Q40: =VLOOKUP(P40,Maestro!E:F,2,0) -> Molienda de Crudo | R40: =VLOOKUP(P40,ORD!$A:$C,3,0) -> 3 | S40: =A40&J40&Q40 -> 7355250321LAMINASMolienda de Crudo | T40: =IFERROR(VLOOKUP(S40,Maestro!$A:$H,8,0),"Producción") -> Láminas | U40: Clinker
...

Sheet TD
A1: Período | B1: (Todas) | J1: ORD | K1: (Todas)
J2: Proceso | K2: (Todas)
A3: ORD | B3: Proceso | C3: Tipo | D3: Cantidad | E3: Valor | F3: Suma de Costo
A4: 1 | B4: Trituración | C4: Arcilla | D4: 238400.87 | E4: 2.5325674e+09 | F4: 10623.146 | J4: Arrastre | K4: Tipo | L4: Cantidad | M4: Valor | N4: Suma de Costo
C5: Caliza | D5: 908193.8 | E5: 1.2694853e+10 | F5: 13978.132 | J5: Clinker | K5: Arcilla | L5: 238400.87 | M5: 2.5325674e+09 | N5: 10623.146
C6: Producción | D6: -1146594.7 | E6: 0 | F6: 0 | K6: Caliza | L6: 1761940.1 | M6: 2.1111604e+10 | N6: 11982.021
C7: Barras y Placas | D7: 1146594.7 | E7: 1.035962e+09 | F7: 903.51194 | K7: Caliza Triturada | L7: 347555.55 | M7: 0 | N7: 0
C8: Material Dique | D8: 1146594.7 | E8: 4.2328095e+08 | F8: 369.16354 | K8: Carbón | L8: 101742.73 | M8: 3.4210282e+10 | N8: 336243.02
C9: Energía | D9: 1456175.2 | E9: 7.6470168e+08 | F9: 525.144 | K9: Carbón Molido | L9: 95434.68 | M9: 0 | N9: 0
C10: Regalías | D10: 1146594.7 | E10: 1.7476606e+08 | F10: 152.42183 | K10: Clinker | L10: 825956.5 | M10: 0 | N10: 0
A11: 2 | B11: Adiciones | C11: Caliza | D11: 602137.06 | E11: 8.4167512e+09 | F11: 13978.132 | K11: Crudo | L11: 1336232.2 | M11: 0 | N11: 0
C12: Producción | D12: -602137.06 | E12: 0 | F12: 0 | K12: Mineral de Hierro | L12: 35775.541 | M12: 1.0083725e+10 | N12: 281860.87
C13: Barras y Placas | D13: 602137.06 | E13: 5.4403802e+08 | F13: 903.51194 | K13: Prehomo | L13: 1144170.2 | M13: 0 | N13: 0
C14: Material Dique | D14: 602137.06 | E14: 2.2228705e+08 | F14: 369.16354 | K14: Producción | L14: -25558259 | M14: 0 | N14: 0
C15: Energía | D15: 764714.07 | E15: 4.0166155e+08 | F15: 525.24409 | K15: Yeso | L15: 71664.583 | M15: 1.6671009e+10 | N15: 232625.49
C16: Regalías | D16: 602137.06 | E16: 71405480 | F16: 118.58675 | K16: Cemento ART | L16: 92101.888 | M16: 0 | N16: 0
A17: 3 | B17: Molienda de Crudo | C17: Caliza | D17: 251609.26 | E17: 0 | F17: 0 | K17: Sacos | L17: 19242063 | M17: 1.9054949e+10 | N17: 990.27577
C18: Mineral de Hierro | D18: 35775.541 | E18: 1.0083725e+10 | F18: 281860.87 | K18: Cemento UG | L18: 787665.77 | M18: 0 | N18: 0
C19: Prehomo | D19: 1144170.2 | E19: 0 | F19: 0 | K19: Gasoil | L19: 1364000 | M19: 768000000 | N19: 563.04985
C20: Producción | D20: -1376343 | E20: 0 | F20: 0 | K20: Cuerpos Moledores | L20: 1376343 | M20: 230000000 | N20: 167.10951
C21: Cuerpos Moledores | D21: 1376343 | E21: 230000000 | F21: 167.10951 | K21: Ductos | L21: 856559.09 | M21: 0 | N21: 0
C22: Láminas | D22: 1376343 | E22: 1.65e+08 | F22: 119.88291 | K22: Enfriador | L22: 856559.09 | M22: 158000000 | N22: 184.45896
C23: Anillos, Tapas y Separadores | D23: 1376343 | E23: 6.8638784e+08 | F23: 498.70407 | K23: Placas | L23: 856559.09 | M23: 1082101107 | N23: 1263.3117
C24: Energía | D24: 20782779 | E24: 1.0913977e+10 | F24: 525.1452 | K24: Refractarios | L24: 856559.09 | M24: 3.0841314e+09 | N24: 3600.6055
A25: 4 | B25: Molienda de Carbón | C25: Carbón | D25: 101742.73 | E25: 3.4210282e+10 | F25: 336243.02 | K25: Sal Marina | L25: 0 | M25: 0 | N25: 0
C26: Producción | D26: -95434.68 | E26: 0 | F26: 0 | K26: Cemento UG TP | L26: 33980.72 | M26: 0 | N26: 0
C27: Descargue Finos Carbón | D27: 20348.546 | E27: 1.7703235e+08 | F27: 8700 | K27: Láminas | L27: 1376343 | M27: 1.65e+08 | N27: 119.88291
C28: Cuerpos Moledores y Láminas | D28: 95434.68 | E28: 361600000 | F28: 3788.979 | K28: Sellado | L28: 856559.09 | M28: 0 | N28: 0
C29: Desatasque De Carbón | D29: 95434.68 | E29: 4.2598263e+08 | F29: 4463.604 | K29: Placas y Segmentos | L29: 1300000 | M29: 1.9792431e+09 | N29: 1522.4947
C30: Energía | D30: 2672171.1 | E30: 1.4032679e+09 | F30: 525.1415 | K30: Anillos, Tapas y Separadores | L30: 1376343 | M30: 6.8638784e+08 | N30: 498.70407
C31: Cargador Carbón | D31: 101742.73 | E31: 6.4352276e+08 | F31: 6325 | K31: Descargue Finos Carbón | L31: 20348.546 | M31: 1.7703235e+08 | N31: 8700
A32: 5 | B32: Clinkerización | C32: Carbón Molido | D32: 95434.68 | E32: 0 | F32: 0 | K32: Cargue Clinker | L32: 30000 | M32: 184800000 | N32: 6160
C33: Crudo | D33: 1336232.2 | E33: 0 | F33: 0 | K33: Dosificador de Sal | L33: 0 | M33: 0 | N33: 0
C34: Producción | D34: -856559.09 | E34: 0 | F34: 0 | K34: Cargue Ck Tolva | L34: 0 | M34: 0 | N34: 0
C35: Gasoil | D35: 64000 | E35: 768000000 | F35: 12000 | K35: Cuerpos Moledores y Láminas | L35: 95434.68 | M35: 361600000 | N35: 3788.979
C36: Ductos | D36: 856559.09 | E36: 0 | F36: 0 | K36: Barras y Placas | L36: 1748731.7 | M36: 1.58e+09 | N36: 903.51194
C37: Enfriador | D37: 856559.09 | E37: 158000000 | F37: 184.45896 | K37: Combustibles Alternos | L37: 0 | M37: 0 | N37: 0
C38: Placas | D38: 856559.09 | E38: 1082101107 | F38: 1263.3117 | K38: CDR | L38: 13374.908 | M38: 4.2562935e+09 | N38: 318229.74
C39: Refractarios | D39: 856559.09 | E39: 3.0841314e+09 | F39: 3600.6055 | K39: Llanta Picada | L39: 3047.6678 | M39: 9.7044632e+08 | N39: 318422.6
C40: Sellado | D40: 856559.09 | E40: 0 | F40: 0 | K40: Aditivo Molienda | L40: 633.12956 | M40: 2.7834655e+09 | N40: 4396360
...

Sheet Costo
E4: PPTO 2026 | L4: REAL 2025 (Estim. Último trim. con 100% bitumi) F25 | R4: VARIACIONES
E5: Var Mtto + Refract | F5: =I15*I10+I25*I19+I37*(I30+I31+I32)+I46*I43+I75*(I73+I72+I69)+I84*(I91+I107+I168) -> 9348748404
D6: ORD 1 | E6: Proceso | F6: Tipo | G6: Consumo | H6: Costo | I6: Total | K6: ORD 1 | L6: Proceso | M6: Tipo | N6: Consumo | O6: Costo | P6: Total | R6: VP | S6: VC | T6: Total
D7: 1 | E7: Trituración | F7: Arcilla | G7: =IFERROR(GETPIVOTDATA(" Cantidad",TD!$A$3,"Proceso",$E$7,"ORD",$D$7,"Tipo",F7)/GETPIVOTDATA(" Cantidad",TD!$A$3,"Proceso",$E$7,"ORD",$D$7,"Tipo","Producción")*-1,0) -> 0.20792079 | H7: =IFERROR(GETPIVOTDATA("Suma de Costo",TD!$A$3,"Proceso",$E$7,"ORD",$D$7,"Tipo",F7),0) -> 10623.146 | I7: =H7*G7 -> 2208.773 | K7: 1 | L7: Trituración | M7: Arcilla | N7: 0.21731513 | O7: 10136.59 | P7: =N7*O7 -> 2202.8343 | R7: =+(O7-H7)*N7 -> -105.73605 | S7: =+(N7-G7)*H7 -> 99.797399 | T7: =+P7-I7 -> -5.9386497
F8: Caliza | G8: =IFERROR(GETPIVOTDATA(" Cantidad",TD!$A$3,"Proceso","Trituración","ORD",1,"Tipo",F8)/GETPIVOTDATA(" Cantidad",TD!$A$3,"Proceso","Trituración","ORD",1,"Tipo","Producción")*-1,0) -> 0.79207921 | H8: =IFERROR(GETPIVOTDATA("Suma de Costo",TD!$A$3,"Proceso",$E$7,"ORD",$D$7,"Tipo",F8),0) -> 13978.132 | I8: =H8*G8 -> 11071.788 | M8: Caliza | N8: 0.78268487 | O8: 13349.966 | P8: =N8*O8 -> 10448.817 | R8: =+(O8-H8)*N8 -> -491.65578 | S8: =+(N8-G8)*H8 -> -131.31526 | T8: =+P8-I8 -> -622.97104
F9: Energía | G9: =GETPIVOTDATA(" Cantidad",TD!$A$3,"Proceso","Trituración","ORD",1,"Tipo",F9)/((GETPIVOTDATA(" Cantidad",TD!$A$3,"Proceso","Trituración","ORD",1,"Tipo","Producción"))*-1) -> 1.27 | H9: =IFERROR(GETPIVOTDATA("Suma de Costo",TD!$A$3,"Proceso",$E$7,"ORD",$D$7,"Tipo",F9),0) -> 525.144 | I9: =H9*G9 -> 666.93287 | M9: Energía | N9: 1.2925727 | O9: 485.33891 | P9: =N9*O9 -> 627.33584 | R9: =+(O9-H9)*N9 -> -51.450966 | S9: =+(N9-G9)*H9 -> 11.853936 | T9: =+P9-I9 -> -39.597031
C10: P | F10: Barras y Placas | G10: =IFERROR(GETPIVOTDATA(" Cantidad",TD!$A$3,"Proceso","Trituración","ORD",1,"Tipo",F10)/GETPIVOTDATA(" Cantidad",TD!$A$3,"Proceso","Trituración","ORD",1,"Tipo","Producción")*-1,0) -> 1 | H10: =IFERROR(GETPIVOTDATA("Suma de Costo",TD!$A$3,"Proceso",$E$7,"ORD",$D$7,"Tipo",F10),0) -> 903.51194 | I10: =H10*G10 -> 903.51194 | M10: Barras y Placas | N10: 1 | O10: 477.17063 | P10: =N10*O10 -> 477.17063 | R10: =+(O10-H10)*N10 -> -426.34131 | S10: =+(N10-G10)*H10 -> 0 | T10: =+P10-I10 -> -426.34131
F11: Material Dique | G11: =IFERROR(GETPIVOTDATA(" Cantidad",TD!$A$3,"Proceso","Trituración","ORD",1,"Tipo",F11)/GETPIVOTDATA(" Cantidad",TD!$A$3,"Proceso","Trituración","ORD",1,"Tipo","Producción")*-1,0) -> 1 | H11: =IFERROR(GETPIVOTDATA("Suma de Costo",TD!$A$3,"Proceso",$E$7,"ORD",$D$7,"Tipo",F11),0) -> 369.16354 | I11: =H11*G11 -> 369.16354 | M11: Material Dique | N11: 0 | O11: 0 | P11: =N11*O11 -> 0 | R11: =+(O11-H11)*N11 -> 0 | S11: =+(N11-G11)*H11 -> -369.16354 | T11: =+P11-I11 -> -369.16354
F12: Desmantelamiento | G12: 1 | H12: =(IFERROR(GETPIVOTDATA("Suma de Costo",TD!$A$3,"Proceso",$E$7,"ORD",$D$7,"Tipo",F12),0)) -> 0 | I12: =H12*G12 -> 0 | M12: Desmantelamiento | N12: 1 | O12: 0 | P12: =N12*O12 -> 0 | R12: =+(O12-H12)*N12 -> 0 | S12: =+(N12-G12)*H12 -> 0 | T12: =+P12-I12 -> 0
F13: Regalías | G13: 1 | H13: =(IFERROR(GETPIVOTDATA("Suma de Costo",TD!$A$3,"Proceso",$E$7,"ORD",$D$7,"Tipo",F13),0)) -> 152.42183 | I13: =H13*G13 -> 152.42183 | M13: Regalías | N13: 1 | O13: 146.6227 | P13: =N13*O13 -> 146.6227 | R13: =+(O13-H13)*N13 -> -5.7991332 | S13: =+(N13-G13)*H13 -> 0 | T13: =+P13-I13 -> -5.7991332
E14: Total Trituración | I14: =SUM(I7:I13) -> 15372.591 | L14: Total Trituración | P14: =SUM(P7:P13) -> 13902.78 | R14: =+SUM(R7:R13) -> -1080.9832 | S14: =+SUM(S7:S13) -> -388.82746 | T14: =+SUM(T7:T13) -> -1469.8107
E15: TN | I15: =IFERROR(GETPIVOTDATA(" Cantidad",TD!$A$3,"Proceso",E7,"ORD",D7,"Tipo","Producción")*-1,0) -> 1146594.7 | L15: TN | P15: 1234040.9
D17: ORD 2 | E17: Proceso | F17: Tipo | G17: Consumo | H17: Costo | I17: Total | K17: ORD 1 | L17: Proceso | M17: Tipo | N17: Consumo | O17: Costo | P17: Total | R17: VP | S17: VC | T17: Total
D18: 2 | E18: Adiciones | F18: Caliza | G18: =IFERROR(GETPIVOTDATA(" Cantidad",TD!$A$3,"Proceso",$E$18,"ORD",$D$18,"Tipo",F18)/GETPIVOTDATA(" Cantidad",TD!$A$3,"Proceso",$E$18,"ORD",$D$18,"Tipo","Producción")*-1,0) -> 1 | H18: =IFERROR(GETPIVOTDATA("Suma de Costo",TD!$A$3,"Proceso",$E$18,"ORD",$D$18,"Tipo",F18),0) -> 13978.132 | I18: =H18*G18 -> 13978.132 | K18: 2 | L18: Adiciones | M18: Caliza | N18: 1 | O18: 13868.791 | P18: =N18*O18 -> 13868.791 | R18: =+(O18-H18)*N18 -> -109.34051 | S18: =+(N18-G18)*H18 -> 0 | T18: =+P18-I18 -> -109.34051
C19: P | F19: Barras y Placas | G19: =IFERROR(GETPIVOTDATA(" Cantidad",TD!$A$3,"Proceso",$E$18,"ORD",$D$18,"Tipo",F19)/GETPIVOTDATA(" Cantidad",TD!$A$3,"Proceso",$E$18,"ORD",$D$18,"Tipo","Producción")*-1,0) -> 1 | H19: =IFERROR(GETPIVOTDATA("Suma de Costo",TD!$A$3,"Proceso",$E$18,"ORD",$D$18,"Tipo",F19),0) -> 903.51194 | I19: =H19*G19 -> 903.51194 | M19: Barras y Placas | N19: 1 | O19: 477.17063 | P19: =N19*O19 -> 477.17063 | R19: =+(O19-H19)*N19 -> -426.34131 | S19: =+(N19-G19)*H19 -> 0 | T19: =+P19-I19 -> -426.34131
F20: Material Dique | G20: =IFERROR(GETPIVOTDATA(" Cantidad",TD!$A$3,"Proceso",$E$18,"ORD",$D$18,"Tipo",F20)/GETPIVOTDATA(" Cantidad",TD!$A$3,"Proceso",$E$18,"ORD",$D$18,"Tipo","Producción")*-1,0) -> 1 | H20: =IFERROR(GETPIVOTDATA("Suma de Costo",TD!$A$3,"Proceso",$E$18,"ORD",$D$18,"Tipo",F20),0) -> 369.16354 | I20: =H20*G20 -> 369.16354 | M20: Material Dique | N20: 0 | O20: 0 | P20: =N20*O20 -> 0 | R20: =+(O20-H20)*N20 -> 0 | S20: =+(N20-G20)*H20 -> -369.16354 | T20: =+P20-I20 -> -369.16354
F21: Desmantelamiento | G21: =IFERROR(GETPIVOTDATA(" Cantidad",TD!$A$3,"Proceso","Trituración","ORD",1,"Tipo",F21)/GETPIVOTDATA(" Cantidad",TD!$A$3,"Proceso","Trituración","ORD",1,"Tipo","Producción")*-1,0)*0+1 -> 1 | H21: =(IFERROR(GETPIVOTDATA("Suma de Costo",TD!$A$3,"Proceso",$E$18,"ORD",$D$18,"Tipo",F21),0)) -> 0 | I21: =H21*G21 -> 0 | M21: Desmantelamiento | N21: 1 | O21: 0 | P21: =N21*O21 -> 0 | R21: =+(O21-H21)*N21 -> 0 | S21: =+(N21-G21)*H21 -> 0 | T21: =+P21-I21 -> 0
F22: Regalías | G22: =IFERROR(GETPIVOTDATA(" Cantidad",TD!$A$3,"Proceso","Trituración","ORD",1,"Tipo",F22)/GETPIVOTDATA(" Cantidad",TD!$A$3,"Proceso","Trituración","ORD",1,"Tipo","Producción")*-1,0)*0+1 -> 1 | H22: =(IFERROR(GETPIVOTDATA("Suma de Costo",TD!$A$3,"Proceso",$E$18,"ORD",$D$18,"Tipo",F22),0)) -> 118.58675 | I22: =H22*G22 -> 118.58675 | M22: Regalías | N22: 1 | O22: 113.59304 | P22: =N22*O22 -> 113.59304 | R22: =+(O22-H22)*N22 -> -4.9937111 | S22: =+(N22-G22)*H22 -> 0 | T22: =+P22-I22 -> -4.9937111
F23: Energía | G23: =GETPIVOTDATA(" Cantidad",TD!$A$3,"Proceso","Adiciones","ORD",2,"Tipo",F23)/((GETPIVOTDATA(" Cantidad",TD!$A$3,"Proceso","Adiciones","ORD",2,"Tipo","Producción"))*-1) -> 1.27 | H23: =IFERROR(GETPIVOTDATA("Suma de Costo",TD!$A$3,"Proceso",$E$18,"ORD",$D$18,"Tipo",F23),0) -> 525.24409 | I23: =H23*G23 -> 667.06 | M23: Energía | N23: 1.2925727 | O23: 485.33891 | P23: =N23*O23 -> 627.33584 | R23: =+(O23-H23)*N23 -> -51.580351 | S23: =+(N23-G23)*H23 -> 11.856195 | T23: =+P23-I23 -> -39.724156
E24: Total Adiciones | I24: =SUM(I18:I23) -> 16036.454 | L24: Total Adiciones | P24: =SUM(P18:P23) -> 15086.891 | R24: =+SUM(R18:R23) -> -592.25588 | S24: =+SUM(S18:S23) -> -357.30735 | T24: =+SUM(T18:T23) -> -949.56323
E25: TN | I25: =IFERROR(GETPIVOTDATA(" Cantidad",TD!$A$3,"Proceso",E18,"ORD",D18,"Tipo","Producción")*-1,0) -> 602137.06 | L25: TN | P25: 484054.62
D27: ORD 3 | E27: Proceso | F27: Tipo | G27: Consumo | H27: Costo | I27: Total | K27: ORD 3 | L27: Proceso | M27: Tipo | N27: Consumo | O27: Costo | P27: Total | R27: VP | S27: VC | T27: Total
